<?xml version="1.0" encoding="utf-8"?>
<!-- This URDF was automatically created by SolidWorks to URDF Exporter! Originally created by Stephen Brawner (brawner@gmail.com) 
     Commit Version: 1.6.0-4-g7f85cfe  Build Version: 1.6.7995.38578
     For more information, please see http://wiki.ros.org/sw_urdf_exporter -->
<robot
  name="Arm_URDF_2026">
  <link
    name="base_link">
    <inertial>
      <origin
        xyz="3.84653360219475E-19 1.62936819250162E-18 -0.0341328821653139"
        rpy="0 0 0" />
      <mass
        value="0.864892134563512" />
      <inertia
        ixx="0.00191876859811616"
        ixy="-3.39237895942118E-19"
        ixz="6.81787506541134E-20"
        iyy="0.00123037859811616"
        iyz="3.87426352662329E-20"
        izz="0.00194695919266471" />
    </inertial>
    <visual>
      <origin
        xyz="0 0 0"
        rpy="0 0 0" />
      <geometry>
        <mesh
          filename="package://simulation/meshes/Arm_URDF_2026/base_link.STL" />
      </geometry>
      <material
        name="">
        <color
          rgba="0.501960784313725 0.501960784313725 0.501960784313725 1" />
      </material>
    </visual>
    <collision>
      <origin
        xyz="0 0 0"
        rpy="0 0 0" />
      <geometry>
        <mesh
          filename="package://simulation/meshes/Arm_URDF_2026/base_link.STL" />
      </geometry>
    </collision>
  </link>
  <link
    name="shoulder_plate">
    <inertial>
      <origin
        xyz="5.08794742628151E-18 -1.92579702269949E-16 0.0600160238534802"
        rpy="0 0 0" />
      <mass
        value="0.218906800388021" />
      <inertia
        ixx="0.00111549148827076"
        ixy="-2.33595804984975E-18"
        ixz="2.49525184688718E-19"
        iyy="0.0006612096112071"
        iyz="-1.11709605937177E-18"
        izz="0.000976648220892923" />
    </inertial>
    <visual>
      <origin
        xyz="0 0 0"
        rpy="0 0 0" />
      <geometry>
        <mesh
          filename="package://simulation/meshes/Arm_URDF_2026/shoulder_plate.STL" />
      </geometry>
      <material
        name="">
        <color
          rgba="0.909803921568627 0.443137254901961 0.0313725490196078 1" />
      </material>
    </visual>
    <collision>
      <origin
        xyz="0 0 0"
        rpy="0 0 0" />
      <geometry>
        <mesh
          filename="package://simulation/meshes/Arm_URDF_2026/shoulder_plate.STL" />
      </geometry>
    </collision>
  </link>
  <joint
    name="shoulder"
    type="revolute">
    <origin
      xyz="0 0 0"
      rpy="0 0 0" />
    <parent
      link="base_link" />
    <child
      link="shoulder_plate" />
    <axis
      xyz="0 0 1" />
    <limit
      lower="-3.1416"
      upper="3.1416"
      effort="0"
      velocity="0" />
  </joint>
  <link
    name="shoulder_tube">
    <inertial>
      <origin
        xyz="0.0934397535393198 0.153473166564317 0.0789999999999963"
        rpy="0 0 0" />
      <mass
        value="1.53763602521836" />
      <inertia
        ixx="0.0311716120782097"
        ixy="-0.00392450317623869"
        ixz="-4.23782427029306E-19"
        iyy="0.0025675148100835"
        iyz="-3.11391018603271E-18"
        izz="0.0329256007856722" />
    </inertial>
    <visual>
      <origin
        xyz="0 0 0"
        rpy="0 0 0" />
      <geometry>
        <mesh
          filename="package://simulation/meshes/Arm_URDF_2026/shoulder_tube.STL" />
      </geometry>
      <material
        name="">
        <color
          rgba="0.250980392156863 0.250980392156863 0.250980392156863 1" />
      </material>
    </visual>
    <collision>
      <origin
        xyz="0 0 0"
        rpy="0 0 0" />
      <geometry>
        <mesh
          filename="package://simulation/meshes/Arm_URDF_2026/shoulder_tube.STL" />
      </geometry>
    </collision>
  </link>
  <joint
    name="shoulder_joint"
    type="revolute">
    <origin
      xyz="0 -0.0625 0.095"
      rpy="1.5708 0 3.1416" />
    <parent
      link="shoulder_plate" />
    <child
      link="shoulder_tube" />
    <axis
      xyz="0 0 -1" />
    <limit
      lower="-3.1416"
      upper="3.1416"
      effort="0"
      velocity="0" />
  </joint>
  <link
    name="elbow_plate">
    <inertial>
      <origin
        xyz="-0.0261022307368617 -1.11022302462516E-16 0.0514469264415673"
        rpy="0 0 0" />
      <mass
        value="0.0520779843414588" />
      <inertia
        ixx="4.41777709651995E-05"
        ixy="2.8882044236066E-21"
        ixz="1.57671201262607E-05"
        iyy="5.61312283203173E-05"
        iyz="2.23628916786052E-23"
        izz="6.26364976063086E-05" />
    </inertial>
    <visual>
      <origin
        xyz="0 0 0"
        rpy="0 0 0" />
      <geometry>
        <mesh
          filename="package://simulation/meshes/Arm_URDF_2026/elbow_plate.STL" />
      </geometry>
      <material
        name="">
        <color
          rgba="0.752941176470588 0 0.752941176470588 1" />
      </material>
    </visual>
    <collision>
      <origin
        xyz="0 0 0"
        rpy="0 0 0" />
      <geometry>
        <mesh
          filename="package://simulation/meshes/Arm_URDF_2026/elbow_plate.STL" />
      </geometry>
    </collision>
  </link>
  <joint
    name="elbow"
    type="revolute">
    <origin
      xyz="0.11007 0.40372 0.0525"
      rpy="-3.1416 0 0" />
    <parent
      link="shoulder_tube" />
    <child
      link="elbow_plate" />
    <axis
      xyz="0 0 -1" />
    <limit
      lower="-3.1416"
      upper="3.1416"
      effort="0"
      velocity="0" />
  </joint>
  <link
    name="wrist">
    <inertial>
      <origin
        xyz="3.58046925441613E-15 3.33066907387547E-16 0.134620995048469"
        rpy="0 0 0" />
      <mass
        value="0.320889143269656" />
      <inertia
        ixx="0.0024419546737531"
        ixy="2.0976783346451E-20"
        ixz="1.16073686945327E-17"
        iyy="0.00252871497722016"
        iyz="-5.27209042104812E-20"
        izz="0.000166391156539952" />
    </inertial>
    <visual>
      <origin
        xyz="0 0 0"
        rpy="0 0 0" />
      <geometry>
        <mesh
          filename="package://simulation/meshes/Arm_URDF_2026/wrist.STL" />
      </geometry>
      <material
        name="">
        <color
          rgba="0.752941176470588 0.752941176470588 0.752941176470588 1" />
      </material>
    </visual>
    <collision>
      <origin
        xyz="0 0 0"
        rpy="0 0 0" />
      <geometry>
        <mesh
          filename="package://simulation/meshes/Arm_URDF_2026/wrist.STL" />
      </geometry>
    </collision>
  </link>
  <joint
    name="elbow_roll"
    type="revolute">
    <origin
      xyz="-0.052 0 0.08"
      rpy="3.1416 1.5708 0" />
    <parent
      link="elbow_plate" />
    <child
      link="wrist" />
    <axis
      xyz="0 0 1" />
    <limit
      lower="-3.1416"
      upper="3.1416"
      effort="0"
      velocity="0" />
  </joint>
  <link
    name="end_effector">
    <inertial>
      <origin
        xyz="-0.0161139391356931 -0.00259180380524526 -4.28823643261467E-15"
        rpy="0 0 0" />
      <mass
        value="0.168430124440615" />
      <inertia
        ixx="4.9380907682992E-05"
        ixy="2.49162208357145E-07"
        ixz="1.24894911363941E-20"
        iyy="0.00018100414119621"
        iyz="-4.57622129740949E-21"
        izz="0.000198242850143219" />
    </inertial>
    <visual>
      <origin
        xyz="0 0 0"
        rpy="0 0 0" />
      <geometry>
        <mesh
          filename="package://simulation/meshes/Arm_URDF_2026/end_effector.STL" />
      </geometry>
      <material
        name="">
        <color
          rgba="0 0.450980392156863 0.643137254901961 1" />
      </material>
    </visual>
    <collision>
      <origin
        xyz="0 0 0"
        rpy="0 0 0" />
      <geometry>
        <mesh
          filename="package://simulation/meshes/Arm_URDF_2026/end_effector.STL" />
      </geometry>
    </collision>
  </link>
  <joint
    name="ee_pitch"
    type="revolute">
    <origin
      xyz="0 0 0.334"
      rpy="3.1416 -1.5708 0" />
    <parent
      link="wrist" />
    <child
      link="end_effector" />
    <axis
      xyz="0 0 -1" />
    <limit
      lower="-3.1416"
      upper="3.1416"
      effort="0"
      velocity="0" />
  </joint>
  <link
    name="gripper">
    <inertial>
      <origin
        xyz="5.06539254985228E-15 2.05391259555654E-15 0.0209653367613958"
        rpy="0 0 0" />
      <mass
        value="0.0277832491665746" />
      <inertia
        ixx="1.66013886897555E-05"
        ixy="-5.40905697064629E-22"
        ixz="-7.75422192159671E-20"
        iyy="4.61873064953396E-05"
        iyz="3.5185893407144E-21"
        izz="3.14806768172064E-05" />
    </inertial>
    <visual>
      <origin
        xyz="0 0 0"
        rpy="0 0 0" />
      <geometry>
        <mesh
          filename="package://simulation/meshes/Arm_URDF_2026/gripper.STL" />
      </geometry>
      <material
        name="">
        <color
          rgba="1 1 1 1" />
      </material>
    </visual>
    <collision>
      <origin
        xyz="0 0 0"
        rpy="0 0 0" />
      <geometry>
        <mesh
          filename="package://simulation/meshes/Arm_URDF_2026/gripper.STL" />
      </geometry>
    </collision>
  </link>
  <joint
    name="ee_roll"
    type="revolute">
    <origin
      xyz="0.045 -0.0025 0"
      rpy="0 1.5708 0" />
    <parent
      link="end_effector" />
    <child
      link="gripper" />
    <axis
      xyz="0 0 -1" />
    <limit
      lower="-3.1416"
      upper="3.1416"
      effort="0"
      velocity="0" />
  </joint>
  <!-- Dummy joint so moveit can config the end effector properly-->
  <link
    name="dummy_ee_link">
    <inertial>
      <origin
        xyz="0 0 0"
        rpy="0 0 0" />
      <mass
        value="0" />
      <inertia
        ixx="0"
        ixy="0"
        ixz="0"
        iyy="0"
        iyz="0"
        izz="0" />
    </inertial>
    <visual>
      <origin
        xyz="0 0 0"
        rpy="0 0 0" />
      <material
        name="">
        <color
          rgba="1 1 1 1" />
      </material>
    </visual>
    <collision>
      <origin
        xyz="0 0 0"
        rpy="0 0 0" />
    </collision>
  </link>
  <joint
    name="dummy_ee_joint"
    type="revolute">
    <origin
      xyz="0 0 0"
      rpy="0 0 0" />
    <parent
      link="gripper" />
    <child
      link="dummy_ee_link" />
    <axis
      xyz="0 0 -1" />
    <limit
      lower="0"
      upper="0"
      effort="0"
      velocity="0" />
  </joint>
</robot>