<?xml version="1.0" encoding="utf-8"?>
<!-- This URDF was automatically created by SolidWorks to URDF Exporter! Originally created by Stephen Brawner (brawner@gmail.com) 
     Commit Version: 1.6.0-4-g7f85cfe  Build Version: 1.6.7995.38578
     For more information, please see http://wiki.ros.org/sw_urdf_exporter -->
<robot
  name="Arm_URDF_2026">
  <link
    name="base_link">
    <inertial>
      <origin
        xyz="-1.0896842021993E-15 0.11001602385348 2.62974765747694E-15"
        rpy="0 0 0" />
      <mass
        value="0.218906800388021" />
      <inertia
        ixx="0.0006612096112071"
        ixy="-3.61965236405788E-20"
        ixz="-3.63959469523336E-20"
        iyy="0.000976648220892924"
        iyz="8.76633233387954E-20"
        izz="0.00111549148827076" />
    </inertial>
    <visual>
      <origin
        xyz="0 0 0"
        rpy="0 0 0" />
      <!--<geometry>
        <mesh
          filename="package://simulation/meshes/Arm_URDF_2026/base_link.STL" />
      </geometry>-->
      <material
        name="">
        <color
          rgba="0.909803921568627 0.443137254901961 0.0313725490196078 1" />
      </material>
    </visual>
    <collision>
      <origin
        xyz="0 0 0"
        rpy="0 0 0" />
      <!--<geometry>
        <mesh
          filename="package://simulation/meshes/Arm_URDF_2026/base_link.STL" />
      </geometry>-->
    </collision>
  </link>
  <link
    name="shoulder_joint">
    <inertial>
      <origin
        xyz="-1.08267095631485E-15 0.0400160238534801 2.62974765747694E-15"
        rpy="0 0 0" />
      <mass
        value="0.218906800388021" />
      <inertia
        ixx="0.0006612096112071"
        ixy="1.38971509809078E-21"
        ixz="-3.63959469523336E-20"
        iyy="0.000976648220892924"
        iyz="8.76633233387954E-20"
        izz="0.00111549148827076" />
    </inertial>
    <visual>
      <origin
        xyz="0 0 0"
        rpy="0 0 0" />
      <geometry>
        <mesh
          filename="package://simulation/meshes/Arm_URDF_2026/shoulder_joint.STL" />
      </geometry>
      <material
        name="">
        <color
          rgba="0.909803921568627 0.443137254901961 0.0313725490196078 1" />
      </material>
    </visual>
    <collision>
      <origin
        xyz="0 0 0"
        rpy="0 0 0" />
      <geometry>
        <mesh
          filename="package://simulation/meshes/Arm_URDF_2026/shoulder_joint.STL" />
      </geometry>
    </collision>
  </link>
  <joint
    name="shoulder_joint"
    type="revolute">
    <origin
      xyz="0 0 0.07"
      rpy="1.5708 0 0" />
    <parent
      link="base_link" />
    <child
      link="shoulder_joint" />
    <axis
      xyz="0 1 0" />
    <limit
      lower="-3.1416"
      upper="3.1416"
      effort="0"
      velocity="0" />
  </joint>
  <link
    name="shoulder_link">
    <inertial>
      <origin
        xyz="-0.11591375226997 -0.0717192699760673 -0.0165000010687019"
        rpy="0 0 0" />
      <mass
        value="1.20128252521836" />
      <inertia
        ixx="0.00154885518943183"
        ixy="-0.00191889999224102"
        ixz="-2.85938195672126E-11"
        iyy="0.0147290555869216"
        iyz="-1.35267032744079E-11"
        izz="0.0156368173006491" />
    </inertial>
    <visual>
      <origin
        xyz="0 0 0"
        rpy="0 0 0" />
      <geometry>
        <mesh
          filename="package://simulation/meshes/Arm_URDF_2026/shoulder_link.STL" />
      </geometry>
      <material
        name="">
        <color
          rgba="0.250980392156863 0.250980392156863 0.250980392156863 1" />
      </material>
    </visual>
    <collision>
      <origin
        xyz="0 0 0"
        rpy="0 0 0" />
      <geometry>
        <mesh
          filename="package://simulation/meshes/Arm_URDF_2026/shoulder_link.STL" />
      </geometry>
    </collision>
  </link>
  <joint
    name="shoulder_link"
    type="revolute">
    <origin
      xyz="0 0.075 0"
      rpy="0 -1.5708 0" />
    <parent
      link="shoulder_joint" />
    <child
      link="shoulder_link" />
    <axis
      xyz="0 0 1" />
    <limit
      lower="-3.1416"
      upper="3.1416"
      effort="0"
      velocity="0" />
  </joint>
  <link
    name="elbow_joint">
    <inertial>
      <origin
        xyz="-0.0261022307368628 -0.0154469264415713 -2.4980018054066E-16"
        rpy="0 0 0" />
      <mass
        value="0.0520779843414588" />
      <inertia
        ixx="4.41777709651995E-05"
        ixy="-1.57671201262607E-05"
        ixz="1.88410710262617E-20"
        iyy="6.26364976063085E-05"
        iyz="1.35462378601193E-20"
        izz="5.61312283203172E-05" />
    </inertial>
    <visual>
      <origin
        xyz="0 0 0"
        rpy="0 0 0" />
      <geometry>
        <mesh
          filename="package://simulation/meshes/Arm_URDF_2026/elbow_joint.STL" />
      </geometry>
      <material
        name="">
        <color
          rgba="0.752941176470588 0 0.752941176470588 1" />
      </material>
    </visual>
    <collision>
      <origin
        xyz="0 0 0"
        rpy="0 0 0" />
      <geometry>
        <mesh
          filename="package://simulation/meshes/Arm_URDF_2026/elbow_joint.STL" />
      </geometry>
    </collision>
  </link>
  <joint
    name="elbow_joint"
    type="revolute">
    <origin
      xyz="-0.306 -0.0855 0.038"
      rpy="-1.5708 0 0" />
    <parent
      link="shoulder_link" />
    <child
      link="elbow_joint" />
    <axis
      xyz="0 1 0" />
    <limit
      lower="-3.1416"
      upper="2.3562"
      effort="0"
      velocity="0" />
  </joint>
  <link
    name="wrist_link">
    <inertial>
      <origin
        xyz="-8.18789480661053E-16 0.133203536886904 -2.77555756156289E-16"
        rpy="0 0 0" />
      <mass
        value="0.317119234558551" />
      <inertia
        ixx="0.00237397330838083"
        ixy="4.65117164831915E-18"
        ixz="2.71026858613978E-20"
        iyy="0.0001656371736795"
        iyz="1.98991508016683E-18"
        izz="0.00246073361184789" />
    </inertial>
    <visual>
      <origin
        xyz="0 0 0"
        rpy="0 0 0" />
      <geometry>
        <mesh
          filename="package://simulation/meshes/Arm_URDF_2026/wrist_link.STL" />
      </geometry>
      <material
        name="">
        <color
          rgba="0.752941176470588 0.752941176470588 0.752941176470588 1" />
      </material>
    </visual>
    <collision>
      <origin
        xyz="0 0 0"
        rpy="0 0 0" />
      <geometry>
        <mesh
          filename="package://simulation/meshes/Arm_URDF_2026/wrist_link.STL" />
      </geometry>
    </collision>
  </link>
  <joint
    name="wrist_link"
    type="revolute">
    <origin
      xyz="-0.052 -0.044 0"
      rpy="0 0 1.5708" />
    <parent
      link="elbow_joint" />
    <child
      link="wrist_link" />
    <axis
      xyz="0 1 0" />
    <limit
      lower="-3.1416"
      upper="3.1416"
      effort="0"
      velocity="0" />
  </joint>
  <link
    name="end_effector">
    <inertial>
      <origin
        xyz="-4.71844785465692E-16 -0.0161139391356878 0.00259180380524709"
        rpy="0 0 0" />
      <mass
        value="0.168430124440614" />
      <inertia
        ixx="0.000198242850143219"
        ixy="2.69456875528164E-19"
        ixz="-6.15402656252294E-21"
        iyy="4.93809076829919E-05"
        iyz="-2.49162208357151E-07"
        izz="0.00018100414119621" />
    </inertial>
    <visual>
      <origin
        xyz="0 0 0"
        rpy="0 0 0" />
      <geometry>
        <mesh
          filename="package://simulation/meshes/Arm_URDF_2026/end_effector.STL" />
      </geometry>
      <material
        name="">
        <color
          rgba="0 0.450980392156863 0.643137254901961 1" />
      </material>
    </visual>
    <collision>
      <origin
        xyz="0 0 0"
        rpy="0 0 0" />
      <geometry>
        <mesh
          filename="package://simulation/meshes/Arm_URDF_2026/end_effector.STL" />
      </geometry>
    </collision>
  </link>
  <joint
    name="end_effector_pitch"
    type="revolute">
    <origin
      xyz="0 0.331 0"
      rpy="0 0 0" />
    <parent
      link="wrist_link" />
    <child
      link="end_effector" />
    <axis
      xyz="1 0 0" />
    <limit
      lower="-3.1416"
      upper="3.1416"
      effort="0"
      velocity="0" />
  </joint>
  <link
    name="gripper">
    <inertial>
      <origin
        xyz="-3.88578058618805E-16 0.0309653367614017 4.71844785465692E-16"
        rpy="0 0 0" />
      <mass
        value="0.0277832491665746" />
      <inertia
        ixx="1.66013886897555E-05"
        ixy="-1.40508068916985E-20"
        ixz="-7.15153802954894E-21"
        iyy="3.14806768172064E-05"
        iyz="-5.86927496894595E-21"
        izz="4.61873064953396E-05" />
    </inertial>
    <visual>
      <origin
        xyz="0 0 0"
        rpy="0 0 0" />
      <geometry>
        <mesh
          filename="package://simulation/meshes/Arm_URDF_2026/gripper.STL" />
      </geometry>
      <material
        name="">
        <color
          rgba="1 1 1 1" />
      </material>
    </visual>
    <collision>
      <origin
        xyz="0 0 0"
        rpy="0 0 0" />
      <geometry>
        <mesh
          filename="package://simulation/meshes/Arm_URDF_2026/gripper.STL" />
      </geometry>
    </collision>
  </link>
  <joint
    name="gripper_roll"
    type="revolute">
    <origin
      xyz="0 0.035 0.0025"
      rpy="0 0 0" />
    <parent
      link="end_effector" />
    <child
      link="gripper" />
    <axis
      xyz="0 1 0" />
    <limit
      lower="-3.1416"
      upper="3.1416"
      effort="0"
      velocity="0" />
  </joint>
</robot>